Workbook

Sheet Executive Summary
A1: BLOOM — At-Home Salon & Beauty Services Platform
A2: Module-Wise Requirements — Executive Summary (Phase 1: Salon & Beauty Home Services)
A3: Prepared for IT Delivery Team | Draft v1.0 | September 2026
A5: Module ID | B5: Module Name | C5: Category | D5: Primary Persona(s) | E5: Platform(s) | F5: Priority | G5: # of Requirements | H5: Module Description
A6: M01 | B6: Customer Onboarding & Profile Management | C6: Customer-Facing | D6: End Customer | E6: Customer Android App, Customer iOS App, Website | F6: P0 | G6: =COUNTIF('Detailed Requirements'!$A$6:$A$5000,A6) -> 6 | H6: Registration, login and profile management for end customers.
A7: M02 | B7: Address & Location Management | C7: Customer-Facing | D7: End Customer | E7: Customer Android App, Customer iOS App, Website | F7: P0 | G7: =COUNTIF('Detailed Requirements'!$A$6:$A$5000,A7) -> 5 | H7: Capture and validate service-delivery addresses and serviceability.
A8: M03 | B8: Service Catalog, Search & Discovery | C8: Customer-Facing | D8: End Customer | E8: Customer Android App, Customer iOS App, Website | F8: P0 | G8: =COUNTIF('Detailed Requirements'!$A$6:$A$5000,A8) -> 6 | H8: Browse, search and evaluate the salon & beauty service catalog.
A9: M04 | B9: Booking, Scheduling & Slot Management | C9: Customer-Facing | D9: End Customer | E9: Customer Android App, Customer iOS App, Website | F9: P0 | G9: =COUNTIF('Detailed Requirements'!$A$6:$A$5000,A9) -> 6 | H9: Core booking flow, from slot selection to confirmation.
A10: M05 | B10: Cart, Pricing, Offers & Coupons | C10: Customer-Facing | D10: End Customer | E10: Customer Android App, Customer iOS App, Website | F10: P0 | G10: =COUNTIF('Detailed Requirements'!$A$6:$A$5000,A10) -> 5 | H10: Transparent, upfront pricing — the platform's core trust differentiator.
A11: M06 | B11: Payments, Wallet & Refunds | C11: Customer-Facing | D11: End Customer | E11: Customer Android App, Customer iOS App, Website | F11: P0 | G11: =COUNTIF('Detailed Requirements'!$A$6:$A$5000,A11) -> 6 | H11: Cashless, secure payment collection and refund handling.
A12: M07 | B12: Live Order Tracking | C12: Customer-Facing | D12: End Customer | E12: Customer Android App, Customer iOS App, Website | F12: P1 | G12: =COUNTIF('Detailed Requirements'!$A$6:$A$5000,A12) -> 5 | H12: Real-time visibility into partner assignment and arrival.
A13: M08 | B13: Ratings, Reviews & Feedback | C13: Customer-Facing | D13: End Customer | E13: Customer Android App, Customer iOS App, Website | F13: P0 | G13: =COUNTIF('Detailed Requirements'!$A$6:$A$5000,A13) -> 4 | H13: Structured feedback loop closing the accountability gap.
A14: M09 | B14: Membership & Subscription Plans | C14: Customer-Facing | D14: End Customer | E14: Customer Android App, Customer iOS App, Website | F14: P1 | G14: =COUNTIF('Detailed Requirements'!$A$6:$A$5000,A14) -> 4 | H14: Recurring-revenue and retention plans.
A15: M10 | B15: Loyalty, Referral & Rewards | C15: Customer-Facing | D15: End Customer | E15: Customer Android App, Customer iOS App, Website | F15: P1 | G15: =COUNTIF('Detailed Requirements'!$A$6:$A$5000,A15) -> 4 | H15: Growth-loop mechanics for acquisition and retention.
A16: M11 | B16: Customer Support, Complaints & SOS | C16: Customer-Facing | D16: End Customer | E16: Customer Android App, Customer iOS App, Website | F16: P0 | G16: =COUNTIF('Detailed Requirements'!$A$6:$A$5000,A16) -> 5 | H16: Support and safety channel for customers.
A17: M12 | B17: Reschedule, Cancellation & Service Guarantee | C17: Customer-Facing | D17: End Customer | E17: Customer Android App, Customer iOS App, Website | F17: P0 | G17: =COUNTIF('Detailed Requirements'!$A$6:$A$5000,A17) -> 4 | H17: Booking-change and quality-remediation workflows.
... A38: M33 | B38: Security, Data Privacy & Compliance | C38: Cross-Platform & Technical | D38: All Personas | E38: All Platforms (Shared Backend) | F38: P0 | G38: =COUNTIF('Detailed Requirements'!$A$6:$A$5000,A38) -> 5 | H38: Non-negotiable platform-wide controls; treated as a first-class module, not an afterthought.
A39: TOTAL | B39: 33 Modules | G39: =SUM(G6:G38) -> 156
A42: Priority Legend | D42: Modules by Category
A43: P0 | B43: Must-Have — required for MVP / Phase 1 launch | D43: Customer-Facing | E43: 12
A44: P1 | B44: Should-Have — targeted within Phase 1, can trail MVP by a sprint or two | D44: Partner-Facing | E44: 7
A45: P2 | B45: Nice-to-Have — candidate for a later release | D45: Inventory & Supply Chain | E45: 1
D46: Admin & Back-Office | E46: 10
D47: Cross-Platform & Technical | E47: 3

Sheet Detailed Requirements
A1: BLOOM — At-Home Salon & Beauty Services Platform
A2: Detailed, Module-Wise Requirements — Full End-to-End Lifecycle
A3: Covers: Pre-Booking -> Booking & Payment -> Fulfilment -> Post-Service -> Partner Lifecycle -> Backend Ops -> Reporting
A5: Module ID | B5: Module Name | C5: Sub-Feature / Requirement | D5: Requirement Description | E5: Persona(s) | F5: Platform(s) | G5: Lifecycle Stage | H5: Priority | I5: Notes / Dependencies
A6: M01 | B6: Customer Onboarding & Profile Management | C6: OTP / SSO Login | D6: Sign-up and login via mobile OTP, email, and Google/Apple/Facebook SSO. | E6: End Customer | F6: Customer Android App, Customer iOS App, Website | G6: Pre-Booking | H6: P0 | I6: Session tokens must expire and refresh securely.
A7: M01 | B7: Customer Onboarding & Profile Management | C7: Profile Setup | D7: Capture name, gender, date of birth, profile photo. | E7: End Customer | F7: Customer Android App, Customer iOS App, Website | G7: Pre-Booking | H7: P0
A8: M01 | B8: Customer Onboarding & Profile Management | C8: Multiple Saved Addresses | D8: Link one or more saved addresses to a single profile. | E8: End Customer | F8: Customer Android App, Customer iOS App, Website | G8: Pre-Booking | H8: P0 | I8: Depends on M02 Address Management.
A9: M01 | B9: Customer Onboarding & Profile Management | C9: Preference Capture | D9: Store language and partner-gender preference where relevant to a service. | E9: End Customer | F9: Customer Android App, Customer iOS App, Website | G9: Pre-Booking | H9: P1
A10: M01 | B10: Customer Onboarding & Profile Management | C10: Guest Checkout | D10: Allow limited booking flow without full registration; convert to full profile post-booking. | E10: End Customer | F10: Customer Android App, Customer iOS App, Website | G10: Pre-Booking | H10: P2 | I10: Optional for launch.
A11: M01 | B11: Customer Onboarding & Profile Management | C11: Account Deletion & Data Export | D11: Self-serve account deletion and personal-data export for compliance. | E11: End Customer | F11: Customer Android App, Customer iOS App, Website | G11: Ongoing | H11: P1 | I11: Required for DPDP Act compliance — see M33.
A12: M02 | B12: Address & Location Management | C12: Saved Addresses | D12: Add, edit and delete multiple addresses tagged Home/Work/Other. | E12: End Customer | F12: Customer Android App, Customer iOS App, Website | G12: Pre-Booking | H12: P0
A13: M02 | B13: Address & Location Management | C13: GPS Auto-Detect | D13: Auto-detect current location on app open for faster booking. | E13: End Customer | F13: Customer Android App, Customer iOS App, Website | G13: Pre-Booking | H13: P0 | I13: Requires device location permission.
A14: M02 | B14: Address & Location Management | C14: Map Pin & Address Search | D14: Google Places-style autocomplete plus manual map-pin drop. | E14: End Customer | F14: Customer Android App, Customer iOS App, Website | G14: Pre-Booking | H14: P0 | I14: Integration: Maps API — see M32.
A15: M02 | B15: Address & Location Management | C15: Serviceability Check | D15: Validate pincode/zone against live-city coverage before showing catalog. | E15: End Customer | F15: Customer Android App, Customer iOS App, Website | G15: Pre-Booking | H15: P0 | I15: Depends on M24 Zone Configuration.
A16: M02 | B16: Address & Location Management | C16: Default Address | D16: Set and reuse a default address for repeat bookings. | E16: End Customer | F16: Customer Android App, Customer iOS App, Website | G16: Pre-Booking | H16: P1
A17: M03 | B17: Service Catalog, Search & Discovery | C17: Category Browsing | D17: Browse by category: Hair, Skin & Face, Hair Removal, Nails, Makeup, Men's Grooming, Body Care, Packages. | E17: End Customer | F17: Customer Android App, Customer iOS App, Website | G17: Pre-Booking | H17: P0
A18: M03 | B18: Service Catalog, Search & Discovery | C18: Keyword Search | D18: Search with auto-suggest across service names and categories. | E18: End Customer | F18: Customer Android App, Customer iOS App, Website | G18: Pre-Booking | H18: P0
A19: M03 | B19: Service Catalog, Search & Discovery | C19: Filter & Sort | D19: Filter/sort results by price, rating, duration and popularity. | E19: End Customer | F19: Customer Android App, Customer iOS App, Website | G19: Pre-Booking | H19: P1
A20: M03 | B20: Service Catalog, Search & Discovery | C20: Service Detail Page | D20: Description, duration, price, add-ons, before/after images and reviews per service. | E20: End Customer | F20: Customer Android App, Customer iOS App, Website | G20: Pre-Booking | H20: P0
A21: M03 | B21: Service Catalog, Search & Discovery | C21: Package / Bundle Builder | D21: Configure bundled packages (e.g., bridal, party-ready) from individual services. | E21: End Customer | F21: Customer Android App, Customer iOS App, Website | G21: Pre-Booking | H21: P1
A22: M03 | B22: Service Catalog, Search & Discovery | C22: City/Zone Catalog Variants | D22: Show only the services, pricing and availability applicable to the customer's zone. | E22: End Customer | F22: Customer Android App, Customer iOS App, Website | G22: Pre-Booking | H22: P0 | I22: Depends on M22 Service Catalog Master.
A23: M04 | B23: Booking, Scheduling & Slot Management | C23: Real-Time Slot Availability | D23: Show live available slots by zone, date and time based on partner capacity. | E23: End Customer | F23: Customer Android App, Customer iOS App, Website | G23: Booking & Payment | H23: P0 | I23: Depends on M24 Dispatch Configuration.
A24: M04 | B24: Booking, Scheduling & Slot Management | C24: Multi-Service Booking | D24: Book multiple services/add-ons in a single visit/booking. | E24: End Customer | F24: Customer Android App, Customer iOS App, Website | G24: Booking & Payment | H24: P0
A25: M04 | B25: Booking, Scheduling & Slot Management | C25: Instant vs Scheduled Booking | D25: Support both immediate on-demand booking and future-dated scheduling. | E25: End Customer | F25: Customer Android App, Customer iOS App, Website | G25: Booking & Payment | H25: P0
A26: M04 | B26: Booking, Scheduling & Slot Management | C26: Preferred-Partner Selection | D26: Allow repeat customers to request the same partner where available. | E26: End Customer | F26: Customer Android App, Customer iOS App, Website | G26: Booking & Payment | H26: P1
A27: M04 | B27: Booking, Scheduling & Slot Management | C27: Booking Confirmation & ETA | D27: Confirm booking with partner-assignment status and estimated arrival window. | E27: End Customer | F27: Customer Android App, Customer iOS App, Website | G27: Booking & Payment | H27: P0
A28: M04 | B28: Booking, Scheduling & Slot Management | C28: Calendar/Reminder Sync | D28: Add booking to device calendar with reminder. | E28: End Customer | F28: Customer Android App, Customer iOS App, Website | G28: Booking & Payment | H28: P2
A29: M05 | B29: Cart, Pricing, Offers & Coupons | C29: Dynamic Cart | D29: Line-item cart reflecting selected services, add-ons and quantities. | E29: End Customer | F29: Customer Android App, Customer iOS App, Website | G29: Booking & Payment | H29: P0
A30: M05 | B30: Cart, Pricing, Offers & Coupons | C30: Coupon Application | D30: Apply and validate coupon codes with eligibility and usage-limit checks. | E30: End Customer | F30: Customer Android App, Customer iOS App, Website | G30: Booking & Payment | H30: P0 | I30: Depends on M23 Offer Configuration.
A31: M05 | B31: Cart, Pricing, Offers & Coupons | C31: Auto-Applied Discounts | D31: First-booking and referral discounts applied automatically where eligible. | E31: End Customer | F31: Customer Android App, Customer iOS App, Website | G31: Booking & Payment | H31: P1
A32: M05 | B32: Cart, Pricing, Offers & Coupons | C32: Tax (GST) Computation | D32: Compute and display applicable GST on the final price. | E32: End Customer | F32: Customer Android App, Customer iOS App, Website | G32: Booking & Payment | H32: P0
A33: M05 | B33: Cart, Pricing, Offers & Coupons | C33: Price Breakup Transparency | D33: Itemized breakup screen shown before payment — no on-site renegotiation. | E33: End Customer | F33: Customer Android App, Customer iOS App, Website | G33: Booking & Payment | H33: P0 | I33: Core trust requirement per business model.
A34: M06 | B34: Payments, Wallet & Refunds | C34: Multiple Payment Modes | D34: UPI, cards, net-banking and wallets at minimum; COD optional/limited. | E34: End Customer | F34: Customer Android App, Customer iOS App, Website | G34: Booking & Payment | H34: P0 | I34: Integration: Payment Gateway — see M32.
A35: M06 | B35: Payments, Wallet & Refunds | C35: In-App Wallet | D35: Store credits, cashback and refund balances for future use. | E35: End Customer | F35: Customer Android App, Customer iOS App, Website | G35: Booking & Payment | H35: P1
A36: M06 | B36: Payments, Wallet & Refunds | C36: Payment Retry & Failure Handling | D36: Graceful retry flow and clear messaging on payment failure. | E36: End Customer | F36: Customer Android App, Customer iOS App, Website | G36: Booking & Payment | H36: P0
A37: M06 | B37: Payments, Wallet & Refunds | C37: Auto-Refund Workflow | D37: Trigger refund-to-source or wallet-credit automatically on eligible cancellations. | E37: End Customer | F37: Customer Android App, Customer iOS App, Website | G37: Post-Service | H37: P0 | I37: Depends on M12 Cancellation & Guarantee.
A38: M06 | B38: Payments, Wallet & Refunds | C38: GST-Compliant Invoicing | D38: Generate downloadable invoice/receipt per booking. | E38: End Customer | F38: Customer Android App, Customer iOS App, Website | G38: Post-Service | H38: P0
A39: M06 | B39: Payments, Wallet & Refunds | C39: Saved/Tokenized Payment Methods | D39: Securely save cards/UPI handles for repeat use (tokenized, PCI-DSS compliant). | E39: End Customer | F39: Customer Android App, Customer iOS App, Website | G39: Booking & Payment | H39: P1 | I39: See M33 Security & Compliance.
A40: M07 | B40: Live Order Tracking | C40: Live Partner Location | D40: Show partner's real-time location on map from dispatch to arrival. | E40: End Customer | F40: Customer Android App, Customer iOS App, Website | G40: Fulfilment | H40: P0 | I40: Integration: Maps/GPS — see M32.
A41: M07 | B41: Live Order Tracking | C41: Booking Status Timeline | D41: Visual status: Confirmed → Partner Assigned → En Route → Arrived → In Service → Completed. | E41: End Customer | F41: Customer Android App, Customer iOS App, Website | G41: Fulfilment | H41: P0
...
